Workbook

Sheet BOM
A1: BOM con prezzi — Carico attivo 60 V / 20 A / 300 W, 4 canali (controllo WiFi Wemos D1 mini Pro) — rev 0.2
A2: Prezzi IVA esclusa, a quantità singola. Celle blu = valori inseriti a mano; cambi e numero di schede nel foglio Parametri.
A4: Categoria | B4: Riferimenti | C4: Q.tà/scheda | D4: Valore | E4: Package | F4: MPN proposto | G4: Distributore | H4: Prezzo unit. | I4: Valuta | J4: Prezzo unit. € | K4: Q.tà totale | L4: Totale € | M4: Stato prezzo | N4: Fonte | O4: Note
A5: Condensatori | B5: C1 | C5: 1 | D5: 100n 100V X7R | E5: 1206 | F5: CC1206KKX7R0BB104 (Yageo) | G5: Comet | H5: 0.02418 | I5: USD | J5: =IF(H5="","",H5*IF(I5="USD",Parametri!$B$3,IF(I5="GBP",Parametri!$B$4,IF(I5="CNY",Parametri!$B$5,1)))) -> 0.0207948 | K5: =C5*Parametri!$B$7 -> 1 | L5: =IF(J5="","",J5*K5) -> 0.0207948 | M5: verificato | N5: https://store.comet.bg/en/Catalogue/Product/37095 | O5: Prezzo a 10 pz
A6: Condensatori | B6: C2 | C6: 1 | D6: 10n 100V X7R | E6: 1206 | F6: generico X7R 100V | G6: LCSC | H6: 0.02 | I6: USD | J6: =IF(H6="","",H6*IF(I6="USD",Parametri!$B$3,IF(I6="GBP",Parametri!$B$4,IF(I6="CNY",Parametri!$B$5,1)))) -> 0.0172 | K6: =C6*Parametri!$B$7 -> 1 | L6: =IF(J6="","",J6*K6) -> 0.0172 | M6: stima
A7: Condensatori | B7: C3,C4,C7,C10,C13,C16,C20,C22,C23,C25-C27,C29 | C7: 13 | D7: 100n | E7: 1206 | F7: 1206B104K500CT (Walsin) o equiv. | G7: LCSC | H7: 0.015 | I7: USD | J7: =IF(H7="","",H7*IF(I7="USD",Parametri!$B$3,IF(I7="GBP",Parametri!$B$4,IF(I7="CNY",Parametri!$B$5,1)))) -> 0.0129 | K7: =C7*Parametri!$B$7 -> 13 | L7: =IF(J7="","",J7*K7) -> 0.1677 | M7: stima | N7: https://www.lcsc.com/product-detail/C93194.html | O7: Usare 100 V dove il nodo vede VLOAD
A8: Condensatori | B8: C5,C8,C11,C14 | C8: 4 | D8: 10n C0G | E8: 1206 | F8: generico C0G/NP0 50V | G8: LCSC | H8: 0.03 | I8: USD | J8: =IF(H8="","",H8*IF(I8="USD",Parametri!$B$3,IF(I8="GBP",Parametri!$B$4,IF(I8="CNY",Parametri!$B$5,1)))) -> 0.0258 | K8: =C8*Parametri!$B$7 -> 4 | L8: =IF(J8="","",J8*K8) -> 0.1032 | M8: stima | O8: Filtro setpoint 16,6 kHz (rev 0.2)
A9: Condensatori | B9: C6,C9,C12,C15 | C9: 4 | D9: 1n C0G | E9: 1206 | F9: generico C0G/NP0 50V | G9: LCSC | H9: 0.02 | I9: USD | J9: =IF(H9="","",H9*IF(I9="USD",Parametri!$B$3,IF(I9="GBP",Parametri!$B$4,IF(I9="CNY",Parametri!$B$5,1)))) -> 0.0172 | K9: =C9*Parametri!$B$7 -> 4 | L9: =IF(J9="","",J9*K9) -> 0.0688 | M9: stima | O9: Compensazione loop (rev 0.2)
A10: Condensatori | B10: C17,C18,C33,C34 | C10: 4 | D10: 100n 50V | E10: 1206 | F10: 1206B104K500CT (Walsin) | G10: LCSC | H10: 0.015 | I10: USD | J10: =IF(H10="","",H10*IF(I10="USD",Parametri!$B$3,IF(I10="GBP",Parametri!$B$4,IF(I10="CNY",Parametri!$B$5,1)))) -> 0.0129 | K10: =C10*Parametri!$B$7 -> 4 | L10: =IF(J10="","",J10*K10) -> 0.0516 | M10: stima | N10: https://www.lcsc.com/product-detail/C93194.html
A11: Condensatori | B11: C19,C21,C28,C31,C32 | C11: 5 | D11: 10u 25V | E11: 1206 | F11: 10u 50V X7R 1206 | G11: LCSC | H11: 0.0667 | I11: USD | J11: =IF(H11="","",H11*IF(I11="USD",Parametri!$B$3,IF(I11="GBP",Parametri!$B$4,IF(I11="CNY",Parametri!$B$5,1)))) -> 0.057362 | K11: =C11*Parametri!$B$7 -> 5 | L11: =IF(J11="","",J11*K11) -> 0.28681 | M11: verificato | N11: https://www.lcsc.com/category/1142.html | O11: Prezzo a 10 pz, parte da 50 V
A12: Condensatori | B12: C24,C30 | C12: 2 | D12: 1u | E12: 1206 | F12: generico X7R 50V | G12: LCSC | H12: 0.02 | I12: USD | J12: =IF(H12="","",H12*IF(I12="USD",Parametri!$B$3,IF(I12="GBP",Parametri!$B$4,IF(I12="CNY",Parametri!$B$5,1)))) -> 0.0172 | K12: =C12*Parametri!$B$7 -> 2 | L12: =IF(J12="","",J12*K12) -> 0.0344 | M12: stima
A13: Condensatori | B13: C35,C36 | C13: 2 | D13: 22u 10V | E13: 1206 | F13: generico X5R/X7R 10V | G13: LCSC | H13: 0.05 | I13: USD | J13: =IF(H13="","",H13*IF(I13="USD",Parametri!$B$3,IF(I13="GBP",Parametri!$B$4,IF(I13="CNY",Parametri!$B$5,1)))) -> 0.043 | K13: =C13*Parametri!$B$7 -> 2 | L13: =IF(J13="","",J13*K13) -> 0.086 | M13: stima | O13: Uscita buck
A14: Diodi | B14: D1 | C14: 1 | D14: Schottky 100V 30A | E14: TO-263 | F14: VS-30CTQ100SPbF | G14: LCSC | H14: 3.5052 | I14: USD | J14: =IF(H14="","",H14*IF(I14="USD",Parametri!$B$3,IF(I14="GBP",Parametri!$B$4,IF(I14="CNY",Parametri!$B$5,1)))) -> 3.014472 | K14: =C14*Parametri!$B$7 -> 1 | L14: =IF(J14="","",J14*K14) -> 3.014472 | M14: verificato | N14: https://www.lcsc.com/product-image/C145332.html | O14: Stock molto basso
A15: Diodi | B15: D2 | C15: 1 | D15: TVS 64V 1500W | E15: SMC | F15: SMCJ64CA | G15: LCSC | H15: 0.25 | I15: USD | J15: =IF(H15="","",H15*IF(I15="USD",Parametri!$B$3,IF(I15="GBP",Parametri!$B$4,IF(I15="CNY",Parametri!$B$5,1)))) -> 0.215 | K15: =C15*Parametri!$B$7 -> 1 | L15: =IF(J15="","",J15*K15) -> 0.215 | M15: stima
A16: Diodi | B16: D3 | C16: 1 | D16: TVS 64V 400W | E16: SMA | F16: SMAJ64CA | G16: LCSC | H16: 0.08 | I16: USD | J16: =IF(H16="","",H16*IF(I16="USD",Parametri!$B$3,IF(I16="GBP",Parametri!$B$4,IF(I16="CNY",Parametri!$B$5,1)))) -> 0.0688 | K16: =C16*Parametri!$B$7 -> 1 | L16: =IF(J16="","",J16*K16) -> 0.0688 | M16: stima
A17: Diodi | B17: D4 | C17: 1 | D17: Schottky 40V 3A | E17: SMA | F17: SS34 | G17: LCSC | H17: 0.03 | I17: USD | J17: =IF(H17="","",H17*IF(I17="USD",Parametri!$B$3,IF(I17="GBP",Parametri!$B$4,IF(I17="CNY",Parametri!$B$5,1)))) -> 0.0258 | K17: =C17*Parametri!$B$7 -> 1 | L17: =IF(J17="","",J17*K17) -> 0.0258 | M17: stima
A18: Diodi | B18: D5 | C18: 1 | D18: LED verde | E18: 1206 | F18: generico | G18: LCSC | H18: 0.03 | I18: USD | J18: =IF(H18="","",H18*IF(I18="USD",Parametri!$B$3,IF(I18="GBP",Parametri!$B$4,IF(I18="CNY",Parametri!$B$5,1)))) -> 0.0258 | K18: =C18*Parametri!$B$7 -> 1 | L18: =IF(J18="","",J18*K18) -> 0.0258 | M18: stima
A19: Protezioni | B19: F1 | C19: 1 | D19: Fusibile ATO 25A | E19: lamellare | F19: 0287025.PXCN (Littelfuse) | G19: RS UK | H19: 0.235 | I19: GBP | J19: =IF(H19="","",H19*IF(I19="USD",Parametri!$B$3,IF(I19="GBP",Parametri!$B$4,IF(I19="CNY",Parametri!$B$5,1)))) -> 0.27025 | K19: =C19*Parametri!$B$7 -> 1 | L19: =IF(J19="","",J19*K19) -> 0.27025 | M19: verificato | N19: https://uk.rs-online.com/web/p/car-fuses/7874154 | O19: Confezione da 10
A20: Protezioni | B20: F1 (portafusibile) | C20: 1 | D20: Portafusibile ATO PCB | E20: THT 2 pin | F20: Littelfuse/Pudenz 2-pin | I20: EUR | J20: =IF(H20="","",H20*IF(I20="USD",Parametri!$B$3,IF(I20="GBP",Parametri!$B$4,IF(I20="CNY",Parametri!$B$5,1)))) | K20: =C20*Parametri!$B$7 -> 1 | L20: =IF(J20="","",J20*K20) | M20: da quotare | O20: Verificare MPN contro footprint
A21: Protezioni | B21: F2 | C21: 1 | D21: PTC 1,5A hold | E21: 1206 | F21: PTC 1206 hold 1,5 A | G21: LCSC | H21: 0.15 | I21: USD | J21: =IF(H21="","",H21*IF(I21="USD",Parametri!$B$3,IF(I21="GBP",Parametri!$B$4,IF(I21="CNY",Parametri!$B$5,1)))) -> 0.129 | K21: =C21*Parametri!$B$7 -> 1 | L21: =IF(J21="","",J21*K21) -> 0.129 | M21: stima | O21: Alzato da 500 mA: ora alimenta buck WiFi + ventola
A22: Connettori | B22: J1,J2 | C22: 2 | D22: Morsetto M5 (bullone) | E22: foro 5,3 mm | F22: Bullone M5 inox + 2 dadi + rondelle | G22: Ferramenta | H22: 0.6 | I22: EUR | J22: =IF(H22="","",H22*IF(I22="USD",Parametri!$B$3,IF(I22="GBP",Parametri!$B$4,IF(I22="CNY",Parametri!$B$5,1)))) -> 0.6 | K22: =C22*Parametri!$B$7 -> 2 | L22: =IF(J22="","",J22*K22) -> 1.2 | M22: stima | O22: Alternativa: Würth REDCUBE M5 7461383 (~2,50 USD, footprint da cambiare)
A23: Connettori | B23: J3 | C23: 1 | D23: Morsetto 2 vie 5 mm | E23: THT | F23: Phoenix MKDS 1,5/2 (1715022) | H23: 0.8 | I23: EUR | J23: =IF(H23="","",H23*IF(I23="USD",Parametri!$B$3,IF(I23="GBP",Parametri!$B$4,IF(I23="CNY",Parametri!$B$5,1)))) -> 0.8 | K23: =C23*Parametri!$B$7 -> 1 | L23: =IF(J23="","",J23*K23) -> 0.8 | M23: stima
A24: Connettori | B24: J4,J5 | C24: 2 | D24: Strip femmina 1x8 2,54 | E24: THT | F24: generico | G24: LCSC | H24: 0.3 | I24: USD | J24: =IF(H24="","",H24*IF(I24="USD",Parametri!$B$3,IF(I24="GBP",Parametri!$B$4,IF(I24="CNY",Parametri!$B$5,1)))) -> 0.258 | K24: =C24*Parametri!$B$7 -> 2 | L24: =IF(J24="","",J24*K24) -> 0.516 | M24: stima | O24: Zoccolo per il Wemos
A25: Connettori | B25: J6,J7 | C25: 2 | D25: Molex KK 4 vie | E25: THT | F25: 22-27-2041 | H25: 0.35 | I25: USD | J25: =IF(H25="","",H25*IF(I25="USD",Parametri!$B$3,IF(I25="GBP",Parametri!$B$4,IF(I25="CNY",Parametri!$B$5,1)))) -> 0.301 | K25: =C25*Parametri!$B$7 -> 2 | L25: =IF(J25="","",J25*K25) -> 0.602 | M25: stima
A26: Connettori | B26: J8 | C26: 1 | D26: Jack DC | E26: THT | F26: PJ-102AH (CUI) | H26: 0.6 | I26: USD | J26: =IF(H26="","",H26*IF(I26="USD",Parametri!$B$3,IF(I26="GBP",Parametri!$B$4,IF(I26="CNY",Parametri!$B$5,1)))) -> 0.516 | K26: =C26*Parametri!$B$7 -> 1 | L26: =IF(J26="","",J26*K26) -> 0.516 | M26: stima
A27: Modulo WiFi | B27: (su J4/J5) | C27: 1 | D27: Wemos LOLIN D1 mini Pro V2 | E27: modulo | F27: LOLIN D1 mini Pro V2 (ESP8266, 16 MB, U.FL) | G27: TinyTronics | H27: 7.44 | I27: EUR | J27: =IF(H27="","",H27*IF(I27="USD",Parametri!$B$3,IF(I27="GBP",Parametri!$B$4,IF(I27="CNY",Parametri!$B$5,1)))) -> 7.44 | K27: =C27*Parametri!$B$7 -> 1 | L27: =IF(J27="","",J27*K27) -> 7.44 | M27: verificato | N27: https://www.tinytronics.nl/shop/nl/communicatie/wi-fi/wemos-lolin-d1-mini-pro-v2-esp8266-ch340c | O27: IVA esclusa; cloni a pochi euro su AliExpress
A28: Magnetici | B28: L1 | C28: 1 | D28: 6,8 µH | E28: 4x4 mm | F28: SRN4018-6R8M (Bourns) | H28: 0.3 | I28: USD | J28: =IF(H28="","",H28*IF(I28="USD",Parametri!$B$3,IF(I28="GBP",Parametri!$B$4,IF(I28="CNY",Parametri!$B$5,1)))) -> 0.258 | K28: =C28*Parametri!$B$7 -> 1 | L28: =IF(J28="","",J28*K28) -> 0.258 | M28: stima
A29: Transistor | B29: Q1,Q2,Q3,Q4 | C29: 4 | D29: MOSFET Linear L2 100V 75A | E29: TO-247 | F29: IXTH75N10L2 | G29: DigiKey | H29: 17.59 | I29: USD | J29: =IF(H29="","",H29*IF(I29="USD",Parametri!$B$3,IF(I29="GBP",Parametri!$B$4,IF(I29="CNY",Parametri!$B$5,1)))) -> 15.1274 | K29: =C29*Parametri!$B$7 -> 4 | L29: =IF(J29="","",J29*K29) -> 60.5096 | M29: verificato | N29: https://www.findchips.com/search/H75N1 | O29: 1 pz; 10,93 USD da 30 pz. Mouser 20,99 USD
A30: Transistor | B30: Q5,Q6,Q7 | C30: 3 | D30: Dual N-MOSFET | E30: SOIC-8 | F30: FDS9926A | H30: 0.4 | I30: USD | J30: =IF(H30="","",H30*IF(I30="USD",Parametri!$B$3,IF(I30="GBP",Parametri!$B$4,IF(I30="CNY",Parametri!$B$5,1)))) -> 0.344 | K30: =C30*Parametri!$B$7 -> 3 | L30: =IF(J30="","",J30*K30) -> 1.032 | M30: stima
A31: Resistori | B31: R1,R15,R21,R27,R33,R44 | C31: 6 | D31: 100R 1% | E31: 1206 | F31: generico | G31: LCSC | H31: 0.005 | I31: USD | J31: =IF(H31="","",H31*IF(I31="USD",Parametri!$B$3,IF(I31="GBP",Parametri!$B$4,IF(I31="CNY",Parametri!$B$5,1)))) -> 0.0043 | K31: =C31*Parametri!$B$7 -> 6 | L31: =IF(J31="","",J31*K31) -> 0.0258 | M31: stima
A32: Resistori | B32: R2,R5,R8,R16,R22,R28,R34,R39,R41,R43,R46 | C32: 11 | D32: 10k 1% | E32: 1206 | F32: generico | G32: LCSC | H32: 0.005 | I32: USD | J32: =IF(H32="","",H32*IF(I32="USD",Parametri!$B$3,IF(I32="GBP",Parametri!$B$4,IF(I32="CNY",Parametri!$B$5,1)))) -> 0.0043 | K32: =C32*Parametri!$B$7 -> 11 | L32: =IF(J32="","",J32*K32) -> 0.0473 | M32: stima
A33: Resistori | B33: R3 | C33: 1 | D33: 10R 1% | E33: 1206 | F33: generico | G33: LCSC | H33: 0.005 | I33: USD | J33: =IF(H33="","",H33*IF(I33="USD",Parametri!$B$3,IF(I33="GBP",Parametri!$B$4,IF(I33="CNY",Parametri!$B$5,1)))) -> 0.0043 | K33: =C33*Parametri!$B$7 -> 1 | L33: =IF(J33="","",J33*K33) -> 0.0043 | M33: stima
A34: Resistori | B34: R4,R14,R20,R26,R32,R36,R40 | C34: 7 | D34: 1k 1% | E34: 1206 | F34: generico | G34: LCSC | H34: 0.005 | I34: USD | J34: =IF(H34="","",H34*IF(I34="USD",Parametri!$B$3,IF(I34="GBP",Parametri!$B$4,IF(I34="CNY",Parametri!$B$5,1)))) -> 0.0043 | K34: =C34*Parametri!$B$7 -> 7 | L34: =IF(J34="","",J34*K34) -> 0.0301 | M34: stima
A35: Resistori | B35: R6,R9 | C35: 2 | D35: 1M 1% | E35: 1206 | F35: generico | G35: LCSC | H35: 0.005 | I35: USD | J35: =IF(H35="","",H35*IF(I35="USD",Parametri!$B$3,IF(I35="GBP",Parametri!$B$4,IF(I35="CNY",Parametri!$B$5,1)))) -> 0.0043 | K35: =C35*Parametri!$B$7 -> 2 | L35: =IF(J35="","",J35*K35) -> 0.0086 | M35: stima
A36: Resistori | B36: R7 | C36: 1 | D36: 249k 1% | E36: 1206 | F36: generico (≥200 V) | G36: LCSC | H36: 0.005 | I36: USD | J36: =IF(H36="","",H36*IF(I36="USD",Parametri!$B$3,IF(I36="GBP",Parametri!$B$4,IF(I36="CNY",Parametri!$B$5,1)))) -> 0.0043 | K36: =C36*Parametri!$B$7 -> 1 | L36: =IF(J36="","",J36*K36) -> 0.0043 | M36: stima
A37: Resistori | B37: R10,R42,R45,R50 | C37: 4 | D37: 100k 1% | E37: 1206 | F37: generico | G37: LCSC | H37: 0.005 | I37: USD | J37: =IF(H37="","",H37*IF(I37="USD",Parametri!$B$3,IF(I37="GBP",Parametri!$B$4,IF(I37="CNY",Parametri!$B$5,1)))) -> 0.0043 | K37: =C37*Parametri!$B$7 -> 4 | L37: =IF(J37="","",J37*K37) -> 0.0172 | M37: stima
A38: Resistori | B38: R11 | C38: 1 | D38: 9k31 1% | E38: 1206 | F38: generico | G38: LCSC | H38: 0.005 | I38: USD | J38: =IF(H38="","",H38*IF(I38="USD",Parametri!$B$3,IF(I38="GBP",Parametri!$B$4,IF(I38="CNY",Parametri!$B$5,1)))) -> 0.0043 | K38: =C38*Parametri!$B$7 -> 1 | L38: =IF(J38="","",J38*K38) -> 0.0043 | M38: stima
A39: Resistori | B39: R12,R18,R24,R30 | C39: 4 | D39: 24k 0,1% | E39: 1206 | F39: thin film 0,1% 25 ppm | G39: LCSC | H39: 0.25 | I39: USD | J39: =IF(H39="","",H39*IF(I39="USD",Parametri!$B$3,IF(I39="GBP",Parametri!$B$4,IF(I39="CNY",Parametri!$B$5,1)))) -> 0.215 | K39: =C39*Parametri!$B$7 -> 4 | L39: =IF(J39="","",J39*K39) -> 0.86 | M39: stima | O39: Partitore 25:1
A40: Resistori | B40: R13,R19,R25,R31 | C40: 4 | D40: 1k 0,1% | E40: 1206 | F40: thin film 0,1% 25 ppm | G40: LCSC | H40: 0.25 | I40: USD | J40: =IF(H40="","",H40*IF(I40="USD",Parametri!$B$3,IF(I40="GBP",Parametri!$B$4,IF(I40="CNY",Parametri!$B$5,1)))) -> 0.215 | K40: =C40*Parametri!$B$7 -> 4 | L40: =IF(J40="","",J40*K40) -> 0.86 | M40: stima
A41: Resistori | B41: R17,R23,R29,R35 | C41: 4 | D41: Shunt 20 mΩ Kelvin | E41: 2512 4T | F41: WSK2512R0200FEA (Vishay) | G41: element14 CN | H41: 23.72 | I41: CNY | J41: =IF(H41="","",H41*IF(I41="USD",Parametri!$B$3,IF(I41="GBP",Parametri!$B$4,IF(I41="CNY",Parametri!$B$5,1)))) -> 2.8464 | K41: =C41*Parametri!$B$7 -> 4 | L41: =IF(J41="","",J41*K41) -> 11.3856 | M41: verificato | N41: https://www.element14.cn/en-CN/vishay/wsk2512r0200fea/current-sense-res-0r02-1-1-w-2512/dp/1107431 | O41: Prezzo a 5 pz, IVA esclusa
...

Sheet Meccanica
A1: Meccanica e accessori (opzionale, non sulla PCB)
A3: Categoria | B3: Descrizione | C3: Q.tà/scheda | D3: Unità | E3: Prezzo unit. | F3: Valuta | G3: Stato prezzo | H3: Fonte | I3: Note | J3: Prezzo unit. € | K3: Q.tà totale | L3: Totale €
A4: Termica | B4: Dissipatore + ventola 12 V 4 fili (cooler socket SP3/TR4, ≥300 W) | C4: 1 | F4: EUR | G4: da quotare | I4: Il PCB è progettato sopra questo cooler | J4: =IF(E4="","",E4*IF(F4="USD",Parametri!$B$3,IF(F4="GBP",Parametri!$B$4,IF(F4="CNY",Parametri!$B$5,1)))) | K4: =C4*Parametri!$B$7 -> 1 | L4: =IF(J4="","",J4*K4)
A5: Termica | B5: Spreader in rame (piatto Cu-ETP, spessore 6 mm, a misura) | C5: 1 | F5: EUR | G5: da quotare | I5: A potenziale VLOAD: va isolato dal cooler | J5: =IF(E5="","",E5*IF(F5="USD",Parametri!$B$3,IF(F5="GBP",Parametri!$B$4,IF(F5="CNY",Parametri!$B$5,1)))) | K5: =C5*Parametri!$B$7 -> 1 | L5: =IF(J5="","",J5*K5)
A6: Termica | B6: Pad termico isolante fra spreader e cooler | C6: 1 | F6: EUR | G6: da quotare | I6: Deve reggere ≥ 100 V | J6: =IF(E6="","",E6*IF(F6="USD",Parametri!$B$3,IF(F6="GBP",Parametri!$B$4,IF(F6="CNY",Parametri!$B$5,1)))) | K6: =C6*Parametri!$B$7 -> 1 | L6: =IF(J6="","",J6*K6)
A7: Termica | B7: NTC 10k B3950 (2 pz, incollate allo spreader) | C7: 2 | E7: 0.5 | F7: EUR | G7: stima | J7: =IF(E7="","",E7*IF(F7="USD",Parametri!$B$3,IF(F7="GBP",Parametri!$B$4,IF(F7="CNY",Parametri!$B$5,1)))) -> 0.5 | K7: =C7*Parametri!$B$7 -> 2 | L7: =IF(J7="","",J7*K7) -> 1
A8: Termica | B8: Pasta termica (MOSFET → spreader) | C8: 1 | E8: 5 | F8: EUR | G8: stima | J8: =IF(E8="","",E8*IF(F8="USD",Parametri!$B$3,IF(F8="GBP",Parametri!$B$4,IF(F8="CNY",Parametri!$B$5,1)))) -> 5 | K8: =C8*Parametri!$B$7 -> 1 | L8: =IF(J8="","",J8*K8) -> 5
A9: Meccanica | B9: Viti M3 + distanziali in nylon | C9: 1 | D9: set | E9: 3 | F9: EUR | G9: stima | J9: =IF(E9="","",E9*IF(F9="USD",Parametri!$B$3,IF(F9="GBP",Parametri!$B$4,IF(F9="CNY",Parametri!$B$5,1)))) -> 3 | K9: =C9*Parametri!$B$7 -> 1 | L9: =IF(J9="","",J9*K9) -> 3
A10: Alimentazione | B10: Alimentatore 12 V ≥ 2 A con jack 5,5/2,1 | C10: 1 | E10: 10 | F10: EUR | G10: stima | J10: =IF(E10="","",E10*IF(F10="USD",Parametri!$B$3,IF(F10="GBP",Parametri!$B$4,IF(F10="CNY",Parametri!$B$5,1)))) -> 10 | K10: =C10*Parametri!$B$7 -> 1 | L10: =IF(J10="","",J10*K10) -> 10
A11: Modulo WiFi | B11: Antenna 2,4 GHz con cavetto U.FL (opzionale, se il case è metallico) | C11: 1 | E11: 3 | F11: EUR | G11: stima | J11: =IF(E11="","",E11*IF(F11="USD",Parametri!$B$3,IF(F11="GBP",Parametri!$B$4,IF(F11="CNY",Parametri!$B$5,1)))) -> 3 | K11: =C11*Parametri!$B$7 -> 1 | L11: =IF(J11="","",J11*K11) -> 3
K13: Totale meccanica | L13: =SUM(L4:L11) -> 22

Sheet Parametri
A1: Parametri e ipotesi
A3: Cambio USD → EUR | B3: 0.86 | C3: Ipotesi, da aggiornare al giorno dell'ordine
A4: Cambio GBP → EUR | B4: 1.15 | C4: Ipotesi, da aggiornare
A5: Cambio CNY → EUR | B5: 0.12 | C5: Ipotesi, da aggiornare (prezzi element14 CN sono IVA esclusa)
A7: Numero di schede | B7: 1 | C7: Moltiplica tutte le quantità della BOM
A10: Note
A11: • Prezzi a quantità singola/piccola (1–10 pz), IVA esclusa, spedizione e dazi esclusi. Rilevati fra ottobre 2025 e ottobre 2026 dalle pagine indicate nella colonna Fonte: vanno riverificati prima dell'ordine.
A12: • Stato 'verificato' = prezzo letto su una pagina distributore; 'stima' = prezzo tipico di mercato per quella classe di componente, non letto su una pagina; 'da quotare' = nessun riferimento affidabile.
A13: • Passivi 1206: il prezzo unitario è basso ma molti distributori vendono a multipli di 10–50 pz; il costo reale d'acquisto dei passivi è dominato dai minimi d'ordine (qualche euro in totale).
A14: • IXTH75N10L2: lead time di fabbrica 21–38 settimane secondo DigiKey; verificare la disponibilità a magazzino prima di confermare il progetto.
A15: • Controllo via WiFi con Wemos LOLIN D1 mini Pro V2 (ESP8266) su strip femmina: l'USB del modulo NON è isolato, usarlo solo per programmare a DUT scollegato. Il modulo V2 è lungo 48 mm: l'antenna sporge di circa 2 cm oltre il bordo destro del PCB.
A16: • DAC8565IAPWR risulta 'Not recommended for new designs' su LCSC; la variante in tubo DAC8565IAPW è ancora in vendita su Mouser/DigiKey.
A17: • VS-30CTQ100SPbF: LCSC mostrava 1 solo pezzo a magazzino; tenere un'alternativa D2PAK 100 V ≥ 30 A.
A18: • PCB JLCPCB 2 strati / 2 oz: traccia/spazio minimo 8 mil (0,2 mm), mentre le piazzole dell'INA228 (MSOP-10) distano 0,15 mm. Verificare con il configuratore o passare a 1 oz sugli strati esterni con ricopertura.
A19: • J1/J2: il footprint attuale è un foro M5 con piazzola, quindi la BOM prevede bullone M5 + dadi + rondelle. I terminali Würth REDCUBE press-fit sono un'alternativa migliore per 25 A ma richiedono un footprint diverso.
A20: • Q5–Q7: il CSV di KiCad duplicava la riga per i simboli multi-unità; qui sono consolidati in 3 package FDS9926A. Idem U3/U6 = 2 package OPA2196.
A21: • Rispetto alla versione con STM32 sono usciti STM32F042, ADuM3160, USB-B, LP2951 e header SWD (circa 12 € in meno di elettronica, più il modulo Wemos).
